Workbook
Name __am1: #REF!
Name __tax1: #REF!
Name __tax2: #REF!
Name __tax3: #REF!
Name __tax4: #REF!
Name _am1: #REF!
Name _tax1: #REF!
Name _tax2: #REF!
Name _tax3: #REF!
Name _tax4: #REF!
Name Área_de_muestra_2: #REF!
Name boxes: #REF!
Name button_area_1: #REF!
Name CCT: #REF!
Name celltips_area: #REF!
Name data1: #REF!
Name data10: #REF!
Name data11: #REF!
Name data12: #REF!
Name data13: #REF!
Name data14: #REF!
Name data15: #REF!
Name data16: #REF!
Name data17: #REF!
Name data18: #REF!
Name data19: #REF!
Name data2: #REF!
Name data20: #REF!
Name data21: #REF!
Name data22: #REF!
Name data23: #REF!
Name data24: #REF!
Name data25: #REF!
Name data26: #REF!
Name data27: #REF!
Name data28: #REF!
Name data29: #REF!
Name data3: #REF!
Name data30: #REF!
Name data31: #REF!
Name data32: #REF!
Name data33: #REF!
Name data34: #REF!
Name data35: #REF!
Name data36: #REF!
Name data37: #REF!
Name data38: #REF!
Name data39: #REF!
Name data4: #REF!
Name data40: #REF!
Name data41: #REF!
Name data42: #REF!
Name data43: #REF!
Name data44: #REF!
Name data45: #REF!
Name data46: #REF!
Name data47: #REF!
Name data48: #REF!
Name data49: #REF!
Name data5: #REF!

Sheet TDA SUR
A1: Ce | B1: Tienda | C1: Rut Del Empleado | D1: Dv | E1: Codigo Empleado | F1: Nombre Completo Empleado | G1: Apellido Paterno | H1: Apellido Materno | I1: Nombre Empleado | J1: Centro Costo | K1: Centro de Costo | L1: Departamento | M1: Cargo | N1: Sexo (F/M) | O1: Fecha Nacimiento | P1: Fecha Indemnizable | Q1: Fecha Inicio Contrato | R1: Fecha Termino Contrato | S1: Tipo Jornada | T1: Rut Empleado Superior | U1: Nacionalidad | V1: Codigo Situacion Contractual | W1: Situacion Contractual | X1: Mail Personal | Y1: Caracteristica sindical
A2: 116 | B2: Falabella Concepcion | C2: 10873491 | D2: 4 | E2: 84042 | F2: SEPULVEDA SAAVEDRA MOISES | G2: SEPULVEDA | H2: SAAVEDRA | I2: Moises | J2: 2710 | K2: Gerencia Pers.Adminis. Y Operaciones | L2: TDA-PREV.PERD. Y PROT.ACTIVOS | M2: Guardia | N2: M | O2: 24664 | P2: 36434 | Q2: 36434 | R2: 219516 | S2: 45 | T2: 10337169 | U2: 1 | V2: 3 | W2: INDEFINIDO | X2: Moisessepulveda84@Gmail.Con | Y2: Sindicato N° 1
A3: 116 | B3: Falabella Concepcion | C3: 13104011 | D3: 3 | E3: 301604 | F3: ROMERO VILLALOBOS GICELA ANDREA | G3: ROMERO | H3: VILLALOBOS | I3: Gicela Andrea | J3: 2710 | K3: Gerencia Pers.Adminis. Y Operaciones | L3: TDA-CAJAS | M3: Cajera(O) - Empaque | N3: F | O3: 27964 | P3: 39027 | Q3: 39027 | R3: 219516 | S3: 45 | T3: 10295876 | U3: 1 | V3: 3 | W3: INDEFINIDO | X3: Gicelaromero.23@Gmail.Com | Y3: Sindicato N° 1
A4: 116 | B4: Falabella Concepcion | C4: 13958570 | D4: 4 | E4: 119002 | F4: BURGOS RIFO PAOLA ALEJANDRA | G4: BURGOS | H4: RIFO | I4: Paola Alejandra | J4: 2710 | K4: Gerencia Pers.Adminis. Y Operaciones | L4: TDA-NIÑAS (2-6) | M4: Asesor De Clientes | N4: F | O4: 29488 | P4: 42506 | Q4: 42506 | R4: 219516 | S4: 45 | T4: 13133110 | U4: 1 | V4: 3 | W4: INDEFINIDO | X4: Paola.Burgos.Rifo@Gmail.Com | Y4: Sindicato N° 1
A5: 116 | B5: Falabella Concepcion | C5: 12971603 | D5: 7 | E5: 152501 | F5: NEIRA LABRAÑA JORGE | G5: NEIRA | H5: LABRAÑA | I5: Jorge | J5: 2710 | K5: Gerencia Pers.Adminis. Y Operaciones | L5: TDA-ZAPATILLAS | M5: Vendedor(A) | N5: M | O5: 27897 | P5: 37351 | Q5: 37351 | R5: 219516 | S5: 40 | T5: 11898996 | U5: 1 | V5: 3 | W5: INDEFINIDO | X5: J_Neira76@Live.Cl | Y5: Sindicato N° 1
A6: 116 | B6: Falabella Concepcion | C6: 12698477 | D6: 4 | E6: 465143 | F6: FUENZALIDA IBARRA GLADYS | G6: FUENZALIDA | H6: IBARRA | I6: Gladys | J6: 2710 | K6: Gerencia Pers.Adminis. Y Operaciones | L6: TDA-CAJAS | M6: Cajera(O) - Empaque | N6: F | O6: 27036 | P6: 38139 | Q6: 38139 | R6: 219516 | S6: 40 | T6: 10295876 | U6: 1 | V6: 3 | W6: INDEFINIDO | X6: Gladysfuenzalida1777@Gmail.Com | Y6: Sindicato N° 1
A7: 116 | B7: Falabella Concepcion | C7: 8572806 | D7: 7 | E7: 137537 | F7: SILVA NAVARRETE MARIA LUISA | G7: SILVA | H7: NAVARRETE | I7: Maria Luisa | J7: 2710 | K7: Gerencia Pers.Adminis. Y Operaciones | L7: TDA-PEQUEÑOS ELECTRODOMÉSTICOS | M7: Vendedor(A) | N7: F | O7: 23744 | P7: 37155 | Q7: 37848 | R7: 219516 | S7: 40 | T7: 15855315 | U7: 1 | V7: 3 | W7: INDEFINIDO | X7: Marialuisasilnavarrete@Gmail.Com | Y7: Sindicato N° 1
A8: 116 | B8: Falabella Concepcion | C8: 14030341 | D8: 0 | E8: 663794 | F8: BECERRA SANCHEZ ALEJANDRA | G8: BECERRA | H8: SANCHEZ | I8: Alejandra | J8: 2710 | K8: Gerencia Pers.Adminis. Y Operaciones | L8: TDA-ISLA CELULARES | M8: Vendedor(A) | N8: F | O8: 29809 | P8: 42037 | Q8: 42037 | R8: 219516 | S8: 45 | T8: 18145928 | U8: 1 | V8: 3 | W8: INDEFINIDO | X8: Alejabesa11@Gmail.Com | Y8: Sindicato N° 1
A9: 116 | B9: Falabella Concepcion | C9: 17344793 | D9: 0 | E9: 640034 | F9: MONCADA MONCADA EDSON | G9: MONCADA | H9: MONCADA | I9: Edson | J9: 2710 | K9: Gerencia Pers.Adminis. Y Operaciones | L9: TDA-CALZADO HOMBRES GENERICO | M9: Vendedor(A) | N9: M | O9: 32799 | P9: 40791 | Q9: 40791 | R9: 219516 | S9: 45 | T9: 9569275 | U9: 1 | V9: 3 | W9: INDEFINIDO | X9: Bknewmm1989@Gmail.Com | Y9: Sindicato N° 1
A10: 116 | B10: Falabella Concepcion | C10: 13623060 | D10: 3 | E10: 781959 | F10: HERRERA MUÑOZ PRISCILLA ISABEL | G10: HERRERA | H10: MUÑOZ | I10: Priscilla Isabel | J10: 2710 | K10: Gerencia Pers.Adminis. Y Operaciones | L10: TDA-RINCON JUVENIL DAMAS GENERICO | M10: Asesor De Clientes | N10: F | O10: 28933 | P10: 43811 | Q10: 43811 | R10: 219516 | S10: 45 | T10: 18109867 | U10: 1 | V10: 3 | W10: INDEFINIDO | X10: Priscilla.Iherrera@Gmail.Com | Y10: Sindicato N° 1
A11: 116 | B11: Falabella Concepcion | C11: 19813667 | D11: 0 | E11: 104744 | F11: ROJAS SAAVEDRA CATALINA PAZ | G11: ROJAS | H11: SAAVEDRA | I11: Catalina Paz | J11: 2710 | K11: Gerencia Pers.Adminis. Y Operaciones | L11: TDA-CAJAS | M11: Cajera(O) - Empaque | N11: F | O11: 35774 | P11: 45125 | Q11: 45125 | R11: 219516 | S11: 10 | T11: 13509559 | U11: 1 | V11: 3 | W11: INDEFINIDO | X11: Cata.R.Saavedra@Gmail.Com | Y11: Sindicato N° 1
A12: 116 | B12: Falabella Concepcion | C12: 20514042 | D12: 5 | E12: 813885 | F12: VALDES CARTES NATALIA ANAIS | G12: VALDES | H12: CARTES | I12: Natalia Anais | J12: 2710 | K12: Gerencia Pers.Adminis. Y Operaciones | L12: TDA-SPORT DAMAS GENERICO | M12: Asesor De Clientes | N12: F | O12: 36662 | P12: 44564 | Q12: 44564 | R12: 219516 | S12: 45 | T12: 18068166 | U12: 1 | V12: 3 | W12: INDEFINIDO | X12: Natyvaldes598@Gmail.Com | Y12: Sindicato N° 1
A13: 116 | B13: Falabella Concepcion | C13: 17224573 | D13: 0 | E13: 774650 | F13: VIVALLO DURAN PAMELA | G13: VIVALLO | H13: DURAN | I13: Pamela | J13: 4356 | K13: Corner Concepcion Click & Collect | L13: TDA-JEFES COMERCIALES | M13: Jefe De Ventas | N13: F | O13: 32883 | P13: 43811 | Q13: 43811 | R13: 219516 | S13: 45 | T13: 11650126 | U13: 1 | V13: 3 | W13: INDEFINIDO | X13: P.Vivalloduran@Gmail.Com | Y13: Aportante Sindicato N°1
... A26: 116 | B26: Falabella Concepcion | C26: 11900816 | D26: 6 | E26: 449075 | F26: RUBIO ORTIZ ERICA | G26: RUBIO | H26: ORTIZ | I26: Erica | J26: 2710 | K26: Gerencia Pers.Adminis. Y Operaciones | L26: TDA-CAJAS | M26: Cajera(O) - Empaque | N26: F | O26: 26176 | P26: 39027 | Q26: 39027 | R26: 219516 | S26: 45 | T26: 10295876 | U26: 1 | V26: 3 | W26: INDEFINIDO | X26: Ericarubio1971@Gmail.Com | Y26: Sindicato N° 1
A27: 116 | B27: Falabella Concepcion | C27: 13133110 | D27: K | E27: 352497 | F27: LAGOS RIFFO MARGOT ANDREA | G27: LAGOS | H27: RIFFO | I27: Margot Andrea | J27: 2710 | K27: Gerencia Pers.Adminis. Y Operaciones | L27: TDA-JEFES COMERCIALES | M27: Jefe De Ventas | N27: F | O27: 28137 | P27: 39118 | Q27: 39118 | R27: 219516 | S27: 45 | T27: 11650126 | U27: 1 | V27: 3 | W27: INDEFINIDO | X27: Margotlagosr@Gmail.Com | Y27: Aportante Sindicato N°1
A28: 116 | B28: Falabella Concepcion | C28: 18411483 | D28: 6 | E28: 593176 | F28: BAEZ VELOSO JAZMIN ANDREA | G28: BAEZ | H28: VELOSO | I28: Jazmin Andrea | J28: 2710 | K28: Gerencia Pers.Adminis. Y Operaciones | L28: TDA-CAJAS | M28: Cajera(O) - Empaque | N28: F | O28: 34132 | P28: 44905 | Q28: 44905 | R28: 219516 | S28: 10 | T28: 10295876 | U28: 1 | V28: 3 | W28: INDEFINIDO | X28: Jazminandreabaez.V@Gmail.Com | Y28: Sindicato N° 1
A29: 116 | B29: Falabella Concepcion | C29: 14206085 | D29: K | E29: 937207 | F29: ESPINOZA BURGOS LIDIA YASMINA | G29: ESPINOZA | H29: BURGOS | I29: Lidia Yasmina | J29: 2710 | K29: Gerencia Pers.Adminis. Y Operaciones | L29: TDA-CONFECCION DAMAS GENERICO | M29: Asesor De Clientes | N29: F | O29: 28965 | P29: 43083 | Q29: 43083 | R29: 219516 | S29: 45 | T29: 18068166 | U29: 1 | V29: 3 | W29: INDEFINIDO | X29: Burgosespinozalidia@Gmail.Com | Y29: Sindicato N° 1
A30: 116 | B30: Falabella Concepcion | C30: 13133825 | D30: 2 | E30: 141305 | F30: ROMERO VALDEBENITO RODRIGO | G30: ROMERO | H30: VALDEBENITO | I30: Rodrigo | J30: 2710 | K30: Gerencia Pers.Adminis. Y Operaciones | L30: TDA-ZAPATILLAS | M30: Vendedor(A) | N30: M | O30: 28070 | P30: 37300 | Q30: 37300 | R30: 219516 | S30: 40 | T30: 11898996 | U30: 1 | V30: 3 | W30: INDEFINIDO | X30: Roromerov.Rr@Gmail.Com | Y30: Sindicato N° 1
A31: 116 | B31: Falabella Concepcion | C31: 12383592 | D31: 1 | E31: 89052 | F31: SEPULVEDA RUIZ JESSICA CECILIA | G31: SEPULVEDA | H31: RUIZ | I31: Jessica Cecilia | J31: 2710 | K31: Gerencia Pers.Adminis. Y Operaciones | L31: TDA-CALZADO DAMAS GENERICO | M31: Vendedor(A) | N31: F | O31: 26712 | P31: 36528 | Q31: 36528 | R31: 219516 | S31: 40 | T31: 18410658 | U31: 1 | V31: 3 | W31: INDEFINIDO | X31: Jessicasepu1973@Gmail.Com | Y31: Sindicato N° 1
A32: 116 | B32: Falabella Concepcion | C32: 11684181 | D32: 9 | E32: 447692 | F32: ALCAMAN ZAMBRANO JAVIER | G32: ALCAMAN | H32: ZAMBRANO | I32: Javier | J32: 2710 | K32: Gerencia Pers.Adminis. Y Operaciones | L32: TDA-MANTENCION | M32: Auxiliar Mantencion | N32: M | O32: 25682 | P32: 34288 | Q32: 34288 | R32: 219516 | S32: 45 | T32: 16489827 | U32: 1 | V32: 3 | W32: INDEFINIDO | X32: Alcamanjavier@Gmail.Com | Y32: Aportante Sindicato N°1
A33: 116 | B33: Falabella Concepcion | C33: 14243235 | D33: 8 | E33: 383449 | F33: OPAZO TORRES PABLO CESAR | G33: OPAZO | H33: TORRES | I33: Pablo Cesar | J33: 2710 | K33: Gerencia Pers.Adminis. Y Operaciones | L33: TDA-ZAPATILLAS | M33: Vendedor(A) | N33: M | O33: 27278 | P33: 39142 | Q33: 39142 | R33: 219516 | S33: 40 | T33: 11898996 | U33: 1 | V33: 3 | W33: INDEFINIDO | X33: Pcopazo_74@Hotmail.Com | Y33: Sindicato N° 1
A34: 116 | B34: Falabella Concepcion | C34: 18266932 | D34: 6 | E34: 709824 | F34: ROA RIQUELME MARCELO | G34: ROA | H34: RIQUELME | I34: Marcelo | J34: 2710 | K34: Gerencia Pers.Adminis. Y Operaciones | L34: TDA-CALZADO DAMAS GENERICO | M34: Asistente De Bodega | N34: M | O34: 33952 | P34: 43563 | Q34: 43563 | R34: 219516 | S34: 45 | T34: 18410658 | U34: 1 | V34: 3 | W34: INDEFINIDO | X34: Roa.Marcelo14@Gmail.Com | Y34: Sindicato N° 1
A35: 116 | B35: Falabella Concepcion | C35: 11351878 | D35: 2 | E35: 774537 | F35: BELMAR FLORES JENNY ELIZABETH | G35: BELMAR | H35: FLORES | I35: Jenny Elizabeth | J35: 2710 | K35: Gerencia Pers.Adminis. Y Operaciones | L35: TDA-CAJAS | M35: Cajera(O) - Empaque | N35: F | O35: 25124 | P35: 45022 | Q35: 45022 | R35: 219516 | S35: 25 | T35: 10295876 | U35: 1 | V35: 3 | W35: INDEFINIDO | X35: Jenny.Elizabeth.Belmar@Gmail.Com | Y35: Sindicato N° 1
A36: 116 | B36: Falabella Concepcion | C36: 8268462 | D36: K | E36: 45667 | F36: CASTRO SILVA LUIS FERNAND | G36: CASTRO | H36: SILVA | I36: Luis Fernand | J36: 2710 | K36: Gerencia Pers.Adminis. Y Operaciones | L36: TDA-CALZADO DAMAS GENERICO | M36: Vendedor(A) | N36: M | O36: 21700 | P36: 34659 | Q36: 32832 | R36: 219516 | S36: 45 | T36: 18410658 | U36: 1 | V36: 3 | W36: INDEFINIDO | X36: Fdo.Castrosilva@Gmail.Com | Y36: Sindicato N° 1
A37: 116 | B37: Falabella Concepcion | C37: 9023864 | D37: 7 | E37: 43516 | F37: HERMOSILLA MONTANARES RAUL | G37: HERMOSILLA | H37: MONTANARES | I37: Raul | J37: 2710 | K37: Gerencia Pers.Adminis. Y Operaciones | L37: TDA-GERENCIA | M37: Gerente De Ventas | N37: M | O37: 22237 | P37: 30124 | Q37: 30124 | R37: 219516 | S37: 45 | T37: 9551422 | U37: 1 | V37: 3 | W37: INDEFINIDO | X37: Rhermosilla1970@Gmail.Com | Y37: No Sindicalizado
A38: 116 | B38: Falabella Concepcion | C38: 9106551 | D38: 7 | E38: 41734 | F38: ACEITON YAÑEZ SANDRA GIOVA | G38: ACEITON | H38: YAÑEZ | I38: Sandra Giova | J38: 2710 | K38: Gerencia Pers.Adminis. Y Operaciones | L38: TDA-TESORERIA | M38: Administrativo De Tesoreria | N38: F | O38: 23649 | P38: 31720 | Q38: 31720 | R38: 219516 | S38: 30 | T38: 10550416 | U38: 1 | V38: 3 | W38: INDEFINIDO | X38: Saceitony@Gmail.Com | Y38: Aportante Sindicato N°1
A39: 116 | B39: Falabella Concepcion | C39: 9423553 | D39: 7 | E39: 50342 | F39: DURAN MORA JOSE | G39: DURAN | H39: MORA | I39: Jose | J39: 2710 | K39: Gerencia Pers.Adminis. Y Operaciones | L39: TDA-PREV.PERD. Y PROT.ACTIVOS | M39: Guardia | N39: M | O39: 24144 | P39: 34142 | Q39: 34142 | R39: 219516 | S39: 45 | T39: 10337169 | U39: 1 | V39: 3 | W39: INDEFINIDO | X39: Josepdm0602@Gmail.Com | Y39: Sindicato N° 1
A40: 116 | B40: Falabella Concepcion | C40: 9430066 | D40: 5 | E40: 41165 | F40: ESPINOZA PANTOJA JUANA LUISA | G40: ESPINOZA | H40: PANTOJA | I40: Juana Luisa | J40: 2710 | K40: Gerencia Pers.Adminis. Y Operaciones | L40: TDA-TESORERIA | M40: Administrativo De Tesoreria | N40: F | O40: 23877 | P40: 34004 | Q40: 34004 | R40: 219516 | S40: 45 | T40: 10550416 | U40: 1 | V40: 3 | W40: INDEFINIDO | X40: Juanitaluisaesp@Gmail.Com | Y40: Aportante Sindicato N°1
A41: 116 | B41: Falabella Concepcion | C41: 9569275 | D41: 3 | E41: 437549 | F41: JARA BELMAR EDITH FABIOL | G41: JARA | H41: BELMAR | I41: Edith Fabiol | J41: 2710 | K41: Gerencia Pers.Adminis. Y Operaciones | L41: TDA-JEFES COMERCIALES | M41: Jefe De Ventas | N41: F | O41: 24230 | P41: 34871 | Q41: 32314 | R41: 219516 | S41: 45 | T41: 9023864 | U41: 1 | V41: 3 | W41: INDEFINIDO | X41: Fabiolajarabelmar@Gmail.Com | Y41: Aportante Sindicato N°1
A42: 116 | B42: Falabella Concepcion | C42: 9987263 | D42: 2 | E42: 45357 | F42: OLIVA SILVA ANA MARIA | G42: OLIVA | H42: SILVA | I42: Ana Maria | J42: 2710 | K42: Gerencia Pers.Adminis. Y Operaciones | L42: TDA-ISLA CELULARES | M42: Vendedor(A) | N42: F | O42: 23744 | P42: 31373 | Q42: 31373 | R42: 219516 | S42: 40 | T42: 18145928 | U42: 1 | V42: 3 | W42: INDEFINIDO | X42: Am.Oliva85@Gmail.Com | Y42: Sindicato N° 1
A43: 116 | B43: Falabella Concepcion | C43: 10075574 | D43: 2 | E43: 40436 | F43: OÑATE PINEDA ADELA DEL CA | G43: OÑATE | H43: PINEDA | I43: Adela Del Ca | J43: 2710 | K43: Gerencia Pers.Adminis. Y Operaciones | L43: TDA-CAJAS | M43: Cajera(O) - Empaque | N43: F | O43: 24684 | P43: 32378 | Q43: 32378 | R43: 219516 | S43: 45 | T43: 10295876 | U43: 1 | V43: 3 | W43: INDEFINIDO | X43: Adelitajaime20@Gmail.Com | Y43: Sindicato N° 1
A44: 116 | B44: Falabella Concepcion | C44: 10295876 | D44: 4 | E44: 82767 | F44: NEIRA CERDA MARIELA | G44: NEIRA | H44: CERDA | I44: Mariela | J44: 2710 | K44: Gerencia Pers.Adminis. Y Operaciones | L44: TDA-CAJAS | M44: Jefe De Cajas | N44: F | O44: 26158 | P44: 36273 | Q44: 36273 | R44: 219516 | S44: 45 | T44: 9551422 | U44: 1 | V44: 3 | W44: INDEFINIDO | X44: Marielakarina.Neiracerda@Gmail.Com | Y44: Aportante Sindicato N°1
A45: 116 | B45: Falabella Concepcion | C45: 10550416 | D45: 0 | E45: 437654 | F45: CERDA MUÑOZ MARTA IVONNE | G45: CERDA | H45: MUÑOZ | I45: Marta Ivonne | J45: 2710 | K45: Gerencia Pers.Adminis. Y Operaciones | L45: TDA-TESORERIA | M45: Encargado De Tesoreria | N45: F | O45: 24127 | P45: 31932 | Q45: 31932 | R45: 219516 | S45: 45 | T45: 9551422 | U45: 1 | V45: 3 | W45: INDEFINIDO | X45: M.Ivonnecerda@Gmail.Com | Y45: Aportante Sindicato N°1
A46: 116 | B46: Falabella Concepcion | C46: 10764369 | D46: 9 | E46: 309192 | F46: SAAVEDRA CAMUS INGRID JACQUELINE | G46: SAAVEDRA | H46: CAMUS | I46: Ingrid Jacqueline | J46: 2710 | K46: Gerencia Pers.Adminis. Y Operaciones | L46: TDA-CAJAS | M46: Cajera(O) - Empaque | N46: F | O46: 24767 | P46: 44837 | Q46: 44837 | R46: 219516 | S46: 30 | T46: 10295876 | U46: 1 | V46: 3 | W46: INDEFINIDO | X46: Saavedraingridca@Gmail.Com | Y46: Sindicato N° 1
A47: 116 | B47: Falabella Concepcion | C47: 10790058 | D47: 6 | E47: 33545 | F47: CARVAJAL WITT ALEJANDRO WE | G47: CARVAJAL | H47: WITT | I47: Alejandro We | J47: 2710 | K47: Gerencia Pers.Adminis. Y Operaciones | L47: TDA-ZAPATILLAS | M47: Vendedor(A) | N47: M | O47: 25952 | P47: 34582 | Q47: 34582 | R47: 219516 | S47: 40 | T47: 11898996 | U47: 1 | V47: 3 | W47: INDEFINIDO | X47: Acarvajalw@Hotmail.Com | Y47: Sindicato N° 1
A48: 116 | B48: Falabella Concepcion | C48: 10838293 | D48: 7 | E48: 45993 | F48: ANTINAO ROCHA RICARDO | G48: ANTINAO | H48: ROCHA | I48: Ricardo | J48: 2710 | K48: Gerencia Pers.Adminis. Y Operaciones | L48: TDA-JEFES COMERCIALES | M48: Jefe De Ventas | N48: M | O48: 25274 | P48: 32844 | Q48: 32844 | R48: 219516 | S48: 45 | T48: 9023864 | U48: 1 | V48: 3 | W48: INDEFINIDO | X48: Rantinao@Hotmail.Es | Y48: Aportante Sindicato N°1
... A55: 116 | B55: Falabella Concepcion | C55: 12524396 | D55: 7 | E55: 437883 | F55: PINO TORO XIMENA ALEJA | G55: PINO | H55: TORO | I55: Ximena Aleja | J55: 2710 | K55: Gerencia Pers.Adminis. Y Operaciones | L55: TDA-AUDIO/VIDEO | M55: Vendedor(A) | N55: F | O55: 26822 | P55: 33482 | Q55: 33482 | R55: 219516 | S55: 40 | T55: 10838293 | U55: 1 | V55: 3 | W55: INDEFINIDO | X55: Ximepino1973@Gmail.Com | Y55: Sindicato N° 1
A56: 116 | B56: Falabella Concepcion | C56: 12528275 | D56: K | E56: 437891 | F56: ORMEÑO GARRIDO SILVIA | G56: ORMEÑO | H56: GARRIDO | I56: Silvia | J56: 2710 | K56: Gerencia Pers.Adminis. Y Operaciones | L56: TDA-COLCHONES | M56: Vendedor(A) | N56: F | O56: 26879 | P56: 34382 | Q56: 34382 | R56: 219516 | S56: 40 | T56: 11679521 | U56: 1 | V56: 3 | W56: INDEFINIDO | X56: Chivi_Marcela@Hotmail.Com | Y56: Sindicato N° 1
A57: 116 | B57: Falabella Concepcion | C57: 13509559 | D57: 1 | E57: 90476 | F57: RIVAS BRAVO NATALIA | G57: RIVAS | H57: BRAVO | I57: Natalia | J57: 2710 | K57: Gerencia Pers.Adminis. Y Operaciones | L57: TDA-JEFES COMERCIALES | M57: Jefe De Ventas | N57: F | O57: 28640 | P57: 35332 | Q57: 35332 | R57: 219516 | S57: 45 | T57: 9023864 | U57: 1 | V57: 3 | W57: INDEFINIDO | X57: Nataliarivasb@Gmail.Com | Y57: Aportante Sindicato N°1
A58: 116 | B58: Falabella Concepcion | C58: 13796532 | D58: 1 | E58: 49484 | F58: AGUILERA VIELMA ALEJANDRA | G58: AGUILERA | H58: VIELMA | I58: Alejandra | J58: 2710 | K58: Gerencia Pers.Adminis. Y Operaciones | L58: TDA-CAJAS | M58: Cajera(O) - Empaque | N58: F | O58: 27012 | P58: 34431 | Q58: 34431 | R58: 219516 | S58: 45 | T58: 10295876 | U58: 1 | V58: 3 | W58: INDEFINIDO | X58: Aleaguileravielma@Gmail.Com | Y58: Sindicato N° 1
...

Sheet TDA CURICO
A1: N° | B1: Rut | C1: Dv | D1: Codigo | E1: Nombre Completo Empleado | F1: Centro Costo | G1: Centro de Costo | H1: Departamento | I1: Cargo | J1: Sexo | K1: Nacimiento | L1: Indemnizable | M1: I. Contrato | N1: Dif | O1: T. Contrato | P1: Jor | Q1: Situacion Contractual | R1: Mail Personal | S1: Sindicato
B2: 20510048 | C2: 2 | D2: 734578 | E2: ACEVEDO PEREZ NICOLAS | F2: 2333 | G2: Gcia. Per.Adm. Y Oper. Curico | H2: TDA- BODEGA CENTRALIZADA | I2: Asistente De Bodega | J2: M | K2: 36915 | L2: 44531 | M2: 44531 | N2: =+IF(Tabla4[[#This Row],[I. Contrato]]=Tabla4[[#This Row],[Indemnizable]],"si","no") -> si | O2: 219516 | P2: 45 | Q2: INDEFINIDO | R2: Nicoperez10mlnjr@Gmail.Com | S2: Sind. N° 1
B3: 13785813 | C3: 4 | D3: 523097 | E3: AGUILAR OYARZO LORETO SAN JUAN | F3: 2333 | G3: Gcia. Per.Adm. Y Oper. Curico | H3: TDA-CONFECCION DAMAS GENERICO | I3: Asesor De Clientes | J3: F | K3: 28985 | L3: 42695 | M3: 42695 | N3: =+IF(Tabla4[[#This Row],[I. Contrato]]=Tabla4[[#This Row],[Indemnizable]],"si","no") -> si | O3: 219516 | P3: 45 | Q3: INDEFINIDO | R3: Loreaguilar1005@Gmail.Com | S3: STFC
B4: 17155397 | C4: 0 | D4: 691771 | E4: AGUILERA AGUILERA JEREMY ALEXSANDER | F4: 2333 | G4: Gcia. Per.Adm. Y Oper. Curico | H4: TDA-AUDIO/VIDEO | I4: Vendedor(A) | J4: M | K4: 32507 | L4: 40742 | M4: 40742 | N4: =+IF(Tabla4[[#This Row],[I. Contrato]]=Tabla4[[#This Row],[Indemnizable]],"si","no") -> si | O4: 219516 | P4: 45 | Q4: INDEFINIDO | R4: Aguilera.Jeremy@Gmail.Com | S4: STFC
B5: 19587888 | C5: 9 | D5: 681792 | E5: ALCAINO ALDANA LUIS ALEXANDER | F5: 2333 | G5: Gcia. Per.Adm. Y Oper. Curico | H5: TDA-ABASTECIMIENTO Y LOGISTICA | I5: Auxiliar De Abastecimiento | J5: M | K5: 35747 | L5: 44711 | M5: 44713 | N5: =+IF(Tabla4[[#This Row],[I. Contrato]]=Tabla4[[#This Row],[Indemnizable]],"si","no") -> no | O5: 219516 | P5: 45 | Q5: INDEFINIDO | R5: Luiz.Alcaino@Gmail.Com | S5: Sind. N° 1
B6: 20758070 | C6: 8 | D6: 658073 | E6: AMPUERO HERNANDEZ SCARLLETE IGNACIA | F6: 2333 | G6: Gcia. Per.Adm. Y Oper. Curico | H6: TDA-NIÑAS (2-6) | I6: Asesor De Clientes | J6: F | K6: 37316 | L6: 44958 | M6: 44958 | N6: =+IF(Tabla4[[#This Row],[I. Contrato]]=Tabla4[[#This Row],[Indemnizable]],"si","no") -> si | O6: 219516 | P6: 20 | Q6: INDEFINIDO | R6: Scarletampuero20@Gmail.Com | S6: Sind. N° 1
B7: 14399370 | C7: 1 | D7: 560693 | E7: APABLAZA RUZ MARIA XIMENA | F7: 2333 | G7: Gcia. Per.Adm. Y Oper. Curico | H7: TDA-MANGO | I7: Asesor De Marca | J7: F | K7: 28763 | L7: 40519 | M7: 40519 | N7: =+IF(Tabla4[[#This Row],[I. Contrato]]=Tabla4[[#This Row],[Indemnizable]],"si","no") -> si | O7: 219516 | P7: 45 | Q7: INDEFINIDO | R7: Ximena.Apablaza@Hotmail.Com | S7: STFC
B8: 17441446 | C8: 7 | D8: 775649 | E8: ARANIZ MARTINEZ DENISSE VANESSA | F8: 2333 | G8: Gcia. Per.Adm. Y Oper. Curico | H8: TDA-DISPLAY | I8: Asistente De Visual | J8: F | K8: 32818 | L8: 44539 | M8: 44539 | N8: =+IF(Tabla4[[#This Row],[I. Contrato]]=Tabla4[[#This Row],[Indemnizable]],"si","no") -> si | O8: 219516 | P8: 45 | Q8: INDEFINIDO | R8: Denissearanizmartinez@Gmail.Com | S8: STFC
B9: 16858860 | C9: 7 | D9: 446777 | E9: ARAVENA VASQUEZ RITA NORMA | F9: 2333 | G9: Gcia. Per.Adm. Y Oper. Curico | H9: TDA-PROBADORES | I9: Trainee De Seguridad | J9: F | K9: 32232 | L9: 45213 | M9: 45213 | N9: =+IF(Tabla4[[#This Row],[I. Contrato]]=Tabla4[[#This Row],[Indemnizable]],"si","no") -> si | O9: 219516 | P9: 45 | Q9: INDEFINIDO | R9: R23232016@Gmail.Com | S9: STFC
B10: 12372987 | C10: 0 | D10: 449857 | E10: ARIN IBAÑEZ HERLINDA ROSA | F10: 2333 | G10: Gcia. Per.Adm. Y Oper. Curico | H10: TDA-ISLA CELULARES | I10: Vendedor(A) | J10: F | K10: 26749 | L10: 37712 | M10: 37712 | N10: =+IF(Tabla4[[#This Row],[I. Contrato]]=Tabla4[[#This Row],[Indemnizable]],"si","no") -> si | O10: 219516 | P10: 40 | Q10: INDEFINIDO | R10: Titi_Arin@Hotmail.Com | S10: Sind. N° 1
B11: 14418277 | C11: 4 | D11: 423637 | E11: ARRIAGADA BRAVO MARIA ANDREA | F11: 2333 | G11: Gcia. Per.Adm. Y Oper. Curico | H11: TDA-ZAPATILLAS | I11: Vendedor(A) | J11: F | K11: 25843 | L11: 39636 | M11: 39636 | N11: =+IF(Tabla4[[#This Row],[I. Contrato]]=Tabla4[[#This Row],[Indemnizable]],"si","no") -> si | O11: 219516 | P11: 45 | Q11: INDEFINIDO | R11: Mab@Live.Cl | S11: Sind. N° 1
B12: 17981399 | C12: 8 | D12: 355763 | E12: AVENDAÑO POBLETE VIVIANA PAZ | F12: 2333 | G12: Gcia. Per.Adm. Y Oper. Curico | H12: TDA-CAJAS | I12: Cajera(O) - Empaque | J12: F | K12: 33884 | L12: 42982 | M12: 42982 | N12: =+IF(Tabla4[[#This Row],[I. Contrato]]=Tabla4[[#This Row],[Indemnizable]],"si","no") -> si | O12: 219516 | P12: 30 | Q12: INDEFINIDO | R12: Paz.Avendano@Hotmail.Com | S12: Sind. N° 1
B13: 20178047 | C13: 0 | D13: 489034 | E13: BARRIOS REYES JOAQUIN FERNANDO | F13: 2333 | G13: Gcia. Per.Adm. Y Oper. Curico | H13: TDA-PROBADORES | I13: Trainee De Seguridad | J13: M | K13: 36194 | L13: 45356 | M13: 45356 | N13: =+IF(Tabla4[[#This Row],[I. Contrato]]=Tabla4[[#This Row],[Indemnizable]],"si","no") -> si | O13: 45443 | P13: 45 | Q13: SEGUNDO PLAZO FIJO | R13: Joakobreyes@Gmail.Com | S13: #N/A
B14: 20122174 | C14: 9 | D14: 911631 | E14: BECERRA BECERRA KARIN CAMILA | F14: 2333 | G14: Gcia. Per.Adm. Y Oper. Curico | H14: TDA-CAJAS | I14: Cajera(O) - Empaque | J14: F | K14: 36249 | L14: 45019 | M14: 45019 | N14: =+IF(Tabla4[[#This Row],[I. Contrato]]=Tabla4[[#This Row],[Indemnizable]],"si","no") -> si | O14: 219516 | P14: 20 | Q14: INDEFINIDO | R14: Karincamilab@Outlook.Com | S14: STFC
B15: 18028807 | C15: 4 | D15: 189618 | E15: BERNAL BAHAMONDES LUIS FELIPE | F15: 2333 | G15: Gcia. Per.Adm. Y Oper. Curico | H15: TDA-PERFUMERIA SEMI SELECTIVA GENERICA | I15: Consultor De Perfumería Mp | J15: M | K15: 33877 | L15: 45180 | M15: 45180 | N15: =+IF(Tabla4[[#This Row],[I. Contrato]]=Tabla4[[#This Row],[Indemnizable]],"si","no") -> si | O15: 219516 | P15: 45 | Q15: INDEFINIDO | R15: Luisfelipebernalb@Gmail.Com | S15: STFC
B16: 20663038 | C16: 8 | D16: 189421 | E16: BRAVO ALISTE CONSTANZA SOLEDAD | F16: 2333 | G16: Gcia. Per.Adm. Y Oper. Curico | H16: TDA-PERFUMERIA SEMI SELECTIVA GENERICA | I16: Consultor De Perfumería Mp | J16: F | K16: 37140 | L16: 45180 | M16: 45180 | N16: =+IF(Tabla4[[#This Row],[I. Contrato]]=Tabla4[[#This Row],[Indemnizable]],"si","no") -> si | O16: 219516 | P16: 20 | Q16: INDEFINIDO | R16: Bravoalistec@Gmail.Com | S16: STFC
B17: 17155794 | C17: 1 | D17: 533092 | E17: BRAVO MORALES JOSE LUIS | F17: 2333 | G17: Gcia. Per.Adm. Y Oper. Curico | H17: TDA-PREV.PERD. Y PROT.ACTIVOS | I17: Guardia | J17: M | K17: 32541 | L17: 43389 | M17: 43389 | N17: =+IF(Tabla4[[#This Row],[I. Contrato]]=Tabla4[[#This Row],[Indemnizable]],"si","no") -> si | O17: 219516 | P17: 45 | Q17: INDEFINIDO | R17: Bravojosem89@Gmail.Com | S17: STFC
B18: 14285937 | C18: 8 | D18: 649015 | E18: BRAVO VERGARA LUZ MARIA | F18: 2333 | G18: Gcia. Per.Adm. Y Oper. Curico | H18: TDA-ISLA CELULARES | I18: Vendedor(A) | J18: F | K18: 27163 | L18: 38443 | M18: 38443 | N18: =+IF(Tabla4[[#This Row],[I. Contrato]]=Tabla4[[#This Row],[Indemnizable]],"si","no") -> si | O18: 219516 | P18: 40 | Q18: INDEFINIDO | R18: Luzmariabravovergara@Gmail.Com | S18: Sind. N° 1
B19: 15850392 | C19: 1 | D19: 114669 | E19: BUENO CUETO RICARDO ANTONIO | F19: 2333 | G19: Gcia. Per.Adm. Y Oper. Curico | H19: TDA-PREV.PERD. Y PROT.ACTIVOS | I19: Guardia | J19: M | K19: 30847 | L19: 44417 | M19: 44417 | N19: =+IF(Tabla4[[#This Row],[I. Contrato]]=Tabla4[[#This Row],[Indemnizable]],"si","no") -> si | O19: 219516 | P19: 45 | Q19: INDEFINIDO | R19: Rbuenocueto@Gmail.Com | S19: STFC
B20: 21609803 | C20: K | D20: 148172 | E20: BUSTOS VARELA MARIA PAZ | F20: 2333 | G20: Gcia. Per.Adm. Y Oper. Curico | H20: TDA-CAJAS | I20: Cajera(O) - Empaque | J20: F | K20: 38167 | L20: 44824 | M20: 44824 | N20: =+IF(Tabla4[[#This Row],[I. Contrato]]=Tabla4[[#This Row],[Indemnizable]],"si","no") -> si | O20: 219516 | P20: 20 | Q20: INDEFINIDO | R20: Varelabustos12@Gmail.Com | S20: STFC
B21: 19768878 | C21: 5 | D21: 843725 | E21: CABRERA LLEVENES ESCARLET BELEN | F21: 2333 | G21: Gcia. Per.Adm. Y Oper. Curico | H21: TDA-PROBADORES | I21: Trainee De Seguridad | J21: F | K21: 36232 | L21: 45264 | M21: 45264 | N21: =+IF(Tabla4[[#This Row],[I. Contrato]]=Tabla4[[#This Row],[Indemnizable]],"si","no") -> si | O21: 219516 | P21: 20 | Q21: INDEFINIDO | R21: Escarletbelenc@Gmail.Com | S21: STFC
B22: 19646819 | C22: 6 | D22: 374962 | E22: CABRERA RIQUELME VALENTINA IGNACIA | F22: 2333 | G22: Gcia. Per.Adm. Y Oper. Curico | H22: TDA-CAJAS | I22: Cajera(O) - Empaque | J22: F | K22: 35532 | L22: 42282 | M22: 42282 | N22: =+IF(Tabla4[[#This Row],[I. Contrato]]=Tabla4[[#This Row],[Indemnizable]],"si","no") -> si | O22: 219516 | P22: 30 | Q22: INDEFINIDO | R22: Valentina.Cr12@Gmail.Com | S22: Sind. N° 1
B23: 19006824 | C23: 2 | D23: 170097 | E23: CACERES HERNANDEZ MICHAEL VALENTIN | F23: 2333 | G23: Gcia. Per.Adm. Y Oper. Curico | H23: TDA-ATENCION DE CLIENTES | I23: Encargado Técnico | J23: M | K23: 34641 | L23: 42706 | M23: 42706 | N23: =+IF(Tabla4[[#This Row],[I. Contrato]]=Tabla4[[#This Row],[Indemnizable]],"si","no") -> si | O23: 219516 | P23: 45 | Q23: INDEFINIDO | R23: Mixelpunto19@Gmail.Com | S23: Sind. N° 1
B24: 17592613 | C24: 5 | D24: 604348 | E24: CALIBAR JARA BARBARA CONSUELO | F24: 2333 | G24: Gcia. Per.Adm. Y Oper. Curico | H24: TDA-CALZADO DAMAS GENERICO | I24: Vendedor(A) | J24: F | K24: 33074 | L24: 43808 | M24: 44652 | N24: =+IF(Tabla4[[#This Row],[I. Contrato]]=Tabla4[[#This Row],[Indemnizable]],"si","no") -> no | O24: 219516 | P24: 30 | Q24: INDEFINIDO | R24: Bccalibarj@Gmail.Com | S24: STFC
B25: 14051199 | C25: 4 | D25: 750921 | E25: CANALES JUICA CAROLINA ANDREA | F25: 2333 | G25: Gcia. Per.Adm. Y Oper. Curico | H25: TDA-CONFECCION DAMAS GENERICO | I25: Asesor De Clientes | J25: F | K25: 29650 | L25: 43318 | M25: 43318 | N25: =+IF(Tabla4[[#This Row],[I. Contrato]]=Tabla4[[#This Row],[Indemnizable]],"si","no") -> si | O25: 219516 | P25: 30 | Q25: INDEFINIDO | R25: Carolinacanales30@Gmail.Com | S25: STFC
B26: 14264186 | C26: 0 | D26: 916056 | E26: CANDIA JOFRE EUGENIA DEL CARMEN | F26: 2333 | G26: Gcia. Per.Adm. Y Oper. Curico | H26: TDA-TESORERIA | I26: Encargado De Tesoreria | J26: F | K26: 25746 | L26: 42968 | M26: 42968 | N26: =+IF(Tabla4[[#This Row],[I. Contrato]]=Tabla4[[#This Row],[Indemnizable]],"si","no") -> si | O26: 219516 | P26: 45 | Q26: INDEFINIDO | R26: Edc.Candiaj@Gmail.Com | S26: Sind. N° 1
B27: 16684048 | C27: 1 | D27: 916064 | E27: CARDENAS VENTEO PATRICIA VALESKA | F27: 2333 | G27: Gcia. Per.Adm. Y Oper. Curico | H27: TDA-ZAPATILLAS | I27: Vendedor(A) | J27: F | K27: 31916 | L27: 42968 | M27: 42968 | N27: =+IF(Tabla4[[#This Row],[I. Contrato]]=Tabla4[[#This Row],[Indemnizable]],"si","no") -> si | O27: 219516 | P27: 45 | Q27: INDEFINIDO | R27: Muriel_1107@Hotmail.Com | S27: Sind. N° 1
B28: 20509166 | C28: 1 | D28: 147397 | E28: CARIAGA GAVILAN GENESIS ISAMAR | F28: 2333 | G28: Gcia. Per.Adm. Y Oper. Curico | H28: TDA-CAJAS | I28: Cajera(O) - Empaque | J28: F | K28: 36790 | L28: 44824 | M28: 44824 | N28: =+IF(Tabla4[[#This Row],[I. Contrato]]=Tabla4[[#This Row],[Indemnizable]],"si","no") -> si | O28: 219516 | P28: 30 | Q28: INDEFINIDO | R28: Genesiscariaga2109@Gmail.Com | S28: STFC
B29: 10658936 | C29: 4 | D29: 593249 | E29: CARRASCO RAMIREZ MARISOL DEL CARMEN | F29: 2333 | G29: Gcia. Per.Adm. Y Oper. Curico | H29: TDA-PREV.PERD. Y PROT.ACTIVOS | I29: Guardia | J29: F | K29: 23471 | L29: 38322 | M29: 38322 | N29: =+IF(Tabla4[[#This Row],[I. Contrato]]=Tabla4[[#This Row],[Indemnizable]],"si","no") -> si | O29: 219516 | P29: 45 | Q29: INDEFINIDO | R29: Cholcarrasco@Gmail.Com | S29: STFC
B30: 19610872 | C30: 6 | D30: 938173 | E30: CELEDON MARDONES NATALIA NOEMI | F30: 2333 | G30: Gcia. Per.Adm. Y Oper. Curico | H30: TDA-SPORT HOMBRES | I30: Asesor De Clientes | J30: F | K30: 35647 | L30: 45019 | M30: 45019 | N30: =+IF(Tabla4[[#This Row],[I. Contrato]]=Tabla4[[#This Row],[Indemnizable]],"si","no") -> si | O30: 219516 | P30: 20 | Q30: INDEFINIDO | R30: Natalia.Celedon.Mardones@Gmail.Com | S30: STFC
B31: 19031187 | C31: 2 | D31: 475475 | E31: CERNA CAMPOS JOSE JERONIMO | F31: 2333 | G31: Gcia. Per.Adm. Y Oper. Curico | H31: TDA-ATENCION DE CLIENTES | I31: Encargado Técnico | J31: M | K31: 34972 | L31: 43284 | M31: 43284 | N31: =+IF(Tabla4[[#This Row],[I. Contrato]]=Tabla4[[#This Row],[Indemnizable]],"si","no") -> si | O31: 219516 | P31: 20 | Q31: INDEFINIDO | R31: Xeocer@Gmail.Com | S31: Sind. N° 1
B32: 19299101 | C32: 3 | D32: 913227 | E32: CESPEDES FUENZALIDA CATALINA DEL PILAR | F32: 2333 | G32: Gcia. Per.Adm. Y Oper. Curico | H32: TDA-DEPORTES GENERICO | I32: Asesor De Clientes | J32: F | K32: 35186 | L32: 41988 | M32: 41988 | N32: =+IF(Tabla4[[#This Row],[I. Contrato]]=Tabla4[[#This Row],[Indemnizable]],"si","no") -> si | O32: 219516 | P32: 45 | Q32: INDEFINIDO | R32: Fcespedescata@Gmail.Com | S32: Sind. N° 1
... B40: 11437358 | C40: 3 | D40: 598941 | E40: CORREA LABBE EXEQUIEL FERNANDO | F40: 2333 | G40: Gcia. Per.Adm. Y Oper. Curico | H40: TDA-JEFES COMERCIALES | I40: Jefe De Ventas | J40: M | K40: 25207 | L40: 40637 | M40: 43282 | N40: =+IF(Tabla4[[#This Row],[I. Contrato]]=Tabla4[[#This Row],[Indemnizable]],"si","no") -> no | O40: 219516 | P40: 45 | Q40: INDEFINIDO | R40: Quelitolabbe@Gmail.Com | S40: Aportante 100%
B41: 17442375 | C41: K | D41: 780421 | E41: DAZA DE LA FUENTE RODOLFO ANDRES | F41: 2333 | G41: Gcia. Per.Adm. Y Oper. Curico | H41: TDA-COMPUTACION | I41: Encargado De Bodega Electro | J41: M | K41: 32908 | L41: 43318 | M41: 43318 | N41: =+IF(Tabla4[[#This Row],[I. Contrato]]=Tabla4[[#This Row],[Indemnizable]],"si","no") -> si | O41: 219516 | P41: 45 | Q41: INDEFINIDO | R41: Rodolfo.Daza@Hotmail.Com | S41: Sind. N° 1
B42: 15138844 | C42: 2 | D42: 703206 | E42: DIAZ DIAZ MARIA JOSE | F42: 2333 | G42: Gcia. Per.Adm. Y Oper. Curico | H42: TDA-CAJAS | I42: Cajera(O) - Empaque | J42: F | K42: 30275 | L42: 44398 | M42: 44398 | N42: =+IF(Tabla4[[#This Row],[I. Contrato]]=Tabla4[[#This Row],[Indemnizable]],"si","no") -> si | O42: 219516 | P42: 30 | Q42: INDEFINIDO | R42: Www.Cotetita_2007@Live.Com | S42: STFC
B43: 10711488 | C43: 2 | D43: 260703 | E43: DIAZ GONZALEZ IRMA MARCELA | F43: 2333 | G43: Gcia. Per.Adm. Y Oper. Curico | H43: TDA-LINEA BLANCA | I43: Vendedor(A) | J43: F | K43: 24151 | L43: 39118 | M43: 39118 | N43: =+IF(Tabla4[[#This Row],[I. Contrato]]=Tabla4[[#This Row],[Indemnizable]],"si","no") -> si | O43: 219516 | P43: 40 | Q43: INDEFINIDO | R43: Marceladiazg13@Gmail.Com | S43: Sind. N° 1
B44: 21478843 | C44: 8 | D44: 147621 | E44: DIAZ SEPULVEDA LEONOR MACKARENA | F44: 2333 | G44: Gcia. Per.Adm. Y Oper. Curico | H44: TDA-SPORT HOMBRES | I44: Asesor De Clientes | J44: F | K44: 37990 | L44: 44824 | M44: 44824 | N44: =+IF(Tabla4[[#This Row],[I. Contrato]]=Tabla4[[#This Row],[Indemnizable]],"si","no") -> si | O44: 219516 | P44: 20 | Q44: INDEFINIDO | R44: Leo.Mack.D.S@Gmail.Com | S44: STFC
B45: 13351507 | C45: 0 | D45: 552763 | E45: DUARTE MIRANDA PRISILA DEL CARMEN | F45: 2333 | G45: Gcia. Per.Adm. Y Oper. Curico | H45: TDA-AUDIO/VIDEO | I45: Vendedor(A) | J45: F | K45: 28608 | L45: 38384 | M45: 38384 | N45: =+IF(Tabla4[[#This Row],[I. Contrato]]=Tabla4[[#This Row],[Indemnizable]],"si","no") -> si | O45: 219516 | P45: 25 | Q45: INDEFINIDO | R45: Prisiduartem@Gmail.Com | S45: STFC
B46: 14287355 | C46: 9 | D46: 506613 | E46: DURAN VALENZUELA LUIS OSVALDO | F46: 2333 | G46: Gcia. Per.Adm. Y Oper. Curico | H46: TDA-PREV.PERD. Y PROT.ACTIVOS | I46: Guardia | J46: M | K46: 27347 | L46: 38005 | M46: 38005 | N46: =+IF(Tabla4[[#This Row],[I. Contrato]]=Tabla4[[#This Row],[Indemnizable]],"si","no") -> si | O46: 219516 | P46: 45 | Q46: INDEFINIDO | R46: Loduranv5@Gmail.Com | S46: STFC
B47: 17981225 | C47: 8 | D47: 476226 | E47: ECHEVERRIA NUÑEZ JUAN ROSENDO | F47: 2333 | G47: Gcia. Per.Adm. Y Oper. Curico | H47: TDA-PREV.PERD. Y PROT.ACTIVOS | I47: Guardia | J47: M | K47: 33829 | L47: 42534 | M47: 42534 | N47: =+IF(Tabla4[[#This Row],[I. Contrato]]=Tabla4[[#This Row],[Indemnizable]],"si","no") -> si | O47: 219516 | P47: 45 | Q47: INDEFINIDO | R47: Juan.Echeverrianunez.12@Gmail.Com | S47: STFC
...

Sheet STFC
A1: n° | B1: Rut | C1: DV | D1: Nombre Completo Empleado | E1: S. base | F1: Jor | G1: Gratif. | H1: Departamento | I1: n° cargo nuevo | J1: cargo nuevo | K1: Cargo Antiguo | L1: Inicio Contrato | M1: ANTIGÜEDAD | N1: Nacimiento | O1: correo | P1: Direccion | Q1: Comuna | R1: celular | S1: Estado Civil | T1: Salud | U1: BONO BRIGADISTA | V1: ASIG. FAMILIAR | W1: BONO PUNT. AUT. | X1: BONO ASIST. AUT. | Y1: MOVIL. | Z1: COLA. | AA1: INCENTIVO CONFIABILIDAD | AB1: ASIG.DE CAJA VENDEDORES | AC1: PREMIO CUMPL.GRUPAL NPS | AD1: PREMIO CUMPL.GRUPAL VTAS | AE1: PREMIO SEMESTRAL | AF1: EXCELENCIA ACADEMICA | AG1: COMISION CONNECT AUT | AH1: BONO TRABAJO NOCTURNO | AI1: QUIEBRE STOCK | AJ1: BENEFICIO NACIMIENTO | AK1: BENEFICIO DEFUNCION | AL1: BONO INVENTARIO | AM1: INCENTIVO PRODUC CAJAS AUT | AN1: COM.EFEC. | AO1: SEMANA CORRIDA | AP1: BONO CLICK AND COLLECT | AQ1: CONCURSO FPAY | AR1: INCENTIVO TIENDA CD/SFS | AS1: PREMIO VENTA TIENDA AUT. | AT1: INCENTIVO SELF CHECK OUT AUT | AU1: PREMIO CLICK AND COLLECT | AV1: PREMIO MARCA | AW1: COMISION CYD
A2: 1 | B2: 13785813 | C2: 4 | D2: AGUILAR OYARZO LORETO SAN JUAN | F2: 45 | G2: CT | H2: TDA-SPORT DAMAS GENERICO | I2: 2866 | J2: Asesor De Clientes | K2: Asesor De Compras | L2: 42695 | M2: =+(TODAY()-L2)/365 -> 8.0575342 | N2: 28985 | O2: Loreaguilar1005@gmail.com | P2: Galilea pasaje tarento 1589 | Q2: Curicó | R2: 966594262 | S2: Casado (a) | T2: FONASA | W2: 18738 | X2: 18738 | Y2: 20460 | Z2: 15520 | AC2: 30000 | AN2: 200 | AO2: 5498 | AP2: 25000 | AQ2: 12825 | AR2: 20000 | AS2: 127783 | AU2: 20000
A3: 2 | B3: 17155397 | C3: 0 | D3: AGUILERA AGUILERA JEREMY ALEXSANDER | F3: 45 | G3: CT | H3: TDA-AUDIO/VIDEO | I3: 679 | J3: Vendedor(A) | K3: Asesor De Compras | L3: 40742 | M3: =+(TODAY()-L3)/365 -> 13.408219 | N3: 32507 | O3: aguilera.jeremy@gmail.com | P3: Apóstol Andrés 1538 | Q3: Curicó | R3: 996407837 | S3: Soltero (a) | T3: ISAPRE | U3: 60000 | Y3: 20460 | Z3: 15520 | AN3: 481515 | AO3: 157272 | AQ3: 1163 | AW3: 14350
A4: 3 | B4: 14399370 | C4: 1 | D4: APABLAZA RUZ MARIA XIMENA | F4: 30 | G4: CT | H4: TDA-CONFECCION DAMAS GENERICO | I4: 2866 | J4: Asesor De Clientes | K4: Asesor De Compras | L4: 40519 | M4: =+(TODAY()-L4)/365 -> 14.019178 | N4: 28763 | O4: Ximena.apablaza@hotmail.com | P4: Luis cruz Martínez 452 Luis cruz | Q4: Curicó | R4: 999482239 | S4: Casado (a) | T4: FONASA | V4: 9571 | W4: 4164 | X4: 4164 | Y4: 8184 | Z4: 6208 | AC4: 20000 | AN4: 2000 | AO4: 2522 | AP4: 16667 | AQ4: 5438 | AR4: 13333 | AS4: 29302 | AU4: 13333
A5: 4 | B5: 17441446 | C5: 7 | D5: ARANIZ MARTINEZ DENISSE VANESSA | F5: 45 | G5: CT | H5: TDA-DISPLAY | I5: 48 | J5: Asistente De Display | K5: Asistente De Display | L5: 44539 | M5: =+(TODAY()-L5)/365 -> 3.0054795 | N5: 32818 | W5: 11243 | X5: 11243 | Y5: 14322 | Z5: 10864 | AO5: 0
A6: 5 | B6: 16858860 | C6: 7 | D6: ARAVENA VASQUEZ RITA NORMA | F6: 20 | G6: CT | H6: TDA-PREV.PERD. Y PROT.ACTIVOS | I6: 653 | J6: Guardia | K6: Guardia | L6: 45213 | M6: =+(TODAY()-L6)/365 -> 1.1589041 | N6: 32232 | O6: R23232023@GMAIL.COM | P6: RAUQUEN. LAS ROSAS, CASA N°9 | Q6: Curico | R6: 96296590
A7: 6 | B7: =+'TDA CURICO'!B13 -> 20178047 | C7: =+'TDA CURICO'!C13 -> 0 | D7: =+'TDA CURICO'!E13 -> BARRIOS REYES JOAQUIN FERNANDO | F7: 45 | G7: CT | H7: TDA-PROBADORES | J7: Trainee De Seguridad | L7: 45356 | M7: =+(TODAY()-L7)/365 -> 0.76712329 | N7: 36194 | O7: Joakobreyes@Gmail.Com
A8: 7 | B8: 20122174 | C8: 9 | D8: BECERRA BECERRA KARIM CAMILA | F8: 20 | G8: CT | H8: TDA-CAJAS | J8: Cajera(O) - Empaque | K8: Asesor De Compras | L8: 45019 | M8: =+(TODAY()-L8)/365 -> 1.690411 | N8: 36249 | O8: karincamilab@outlook.com | P8: Villa Doña Carmen, pasaje los Jasminez | R8: 965153719
A9: 8 | B9: 18028807 | C9: 4 | D9: BERNAL BAHAMONDES LUIS FELIPE | F9: 45 | G9: CT | H9: TDA-PERFUMERIA SELECTIVA GENERICA | I9: 2866 | J9: Consultor Perfumeria | K9: Consultor Perfumeria | L9: 45180 | M9: =+(TODAY()-L9)/365 -> 1.2493151 | N9: 33877 | O9: luisfelipebernalb@gmail.com | P9: Cloroformo Valenzuela #760, depto. D-54 | Q9: Curico | R9: 949815248
A10: 9 | B10: 20663038 | C10: 8 | D10: BRAVO ALISTE CONSTANZA SOLEDAD | F10: 20 | G10: CT | H10: TDA-PERFUMERIA SELECTIVA GENERICA | I10: 2866 | J10: Consultor Perfumeria | K10: Consultor Perfumeria | L10: 45180 | M10: =+(TODAY()-L10)/365 -> 1.2493151 | N10: 45175 | O10: bravoalistec@gmail.com | P10: Maria Luisa Bombal #1555 | Q10: Curico | R10: 935833649
A11: 10 | B11: 17155794 | C11: 1 | D11: BRAVO MORALES JOSE LUIS | F11: 45 | G11: CT | H11: TDA-PREV.PERD. Y PROT.ACTIVOS | I11: 653 | J11: Guardia | K11: Guardia | L11: 43389 | M11: =+(TODAY()-L11)/365 -> 6.1561644 | N11: 32541 | W11: 18738 | X11: 18738 | Y11: 17391 | Z11: 13192 | AL11: 24655 | AO11: 0
A12: 11 | B12: 15850392 | C12: 1 | D12: BUENO CUETO RICARDO ANTONIO | F12: 45 | G12: CT | H12: TDA-PREV.PERD. Y PROT.ACTIVOS | I12: 653 | J12: Guardia | K12: Guardia | L12: 44417 | M12: =+(TODAY()-L12)/365 -> 3.339726 | N12: 30847 | W12: 18738 | X12: 18738 | Y12: 22506 | Z12: 17072 | AH12: 30000 | AO12: 0
A13: 12 | B13: 21609803 | C13: K | D13: BUSTOS VARELA MARIA PAZ | F13: 20 | G13: CT | H13: TDA-CAJAS | I13: 741 | J13: Cajera(O) - Empaque | K13: Cajera(O) - Empaque | L13: 44826 | M13: =+(TODAY()-L13)/365 -> 2.2191781 | N13: 38167
A14: 13 | B14: 19768878 | C14: 5 | D14: CABRERA LLEVENES ESCARLET BELEN | F14: 20 | G14: CT | H14: TDA-PREV.PERD. Y PROT.ACTIVOS | I14: 653 | J14: Guardia | K14: Guardia | L14: 45264 | M14: =+(TODAY()-L14)/365 -> 1.0191781 | N14: 36232 | O14: escarletbelén@gmail.com | P14: Valles de Casa Blanca pasaje 14 | Q14: Molina | R14: 990032465
A15: 14 | B15: 17592613 | C15: 5 | D15: CALIBAR JARA BARBARA CONSUELO | F15: 30 | G15: CT | H15: TDA-CALZADO DAMAS GENERICO | I15: 679 | J15: Vendedor(A) | K15: Vendedor(A) | L15: 43800 | M15: =+(TODAY()-L15)/365 -> 5.030137 | N15: 33074 | O15: b.cabilar.portia@gmail.com | P15: Hacienda El Boldo II calle Lleuque #2638 | Q15: Curico | R15: 955312076
A16: 15 | B16: 14051199 | C16: 4 | D16: CANALES JUICA CAROLINA ANDREA | F16: 30 | G16: CT | H16: TDA-CONFECCION DAMAS GENERICO | I16: 2866 | J16: Asesor De Clientes | K16: Asesor De Compras | L16: 43318 | M16: =+(TODAY()-L16)/365 -> 6.3506849 | N16: 29650 | O16: carolinacanales30@gmail.com | P16: Pob. Villa Los Niches psje. 30 de Julio #127 | Q16: Curicó | R16: 957448709 | S16: Casado (a) | T16: FONASA | W16: 12492 | X16: 12492 | Y16: 17391 | Z16: 13192 | AC16: 20000 | AO16: 2541 | AP16: 16667 | AQ16: 7200 | AR16: 13333 | AS16: 82214 | AU16: 13333
A17: 16 | B17: 20509166 | C17: 1 | D17: CARIAGA GAVILAN GENESIS ISAMAR | F17: 30 | G17: CT | H17: TDA-CAJAS | I17: 741 | J17: Cajera(O) - Empaque | K17: Cajera(O) - Empaque | L17: 44824 | M17: =+(TODAY()-L17)/365 -> 2.2246575 | N17: 36790
A18: 17 | B18: 10658936 | C18: 4 | D18: CARRASCO RAMIREZ MARISOL DEL CARMEN | F18: 45 | G18: ST | H18: TDA-PREV.PERD. Y PROT.ACTIVOS | I18: 653 | J18: Guardia | K18: Guardia | L18: 38322 | M18: =+(TODAY()-L18)/365 -> 20.038356 | N18: 23471 | O18: amanda.sofia.quilhot@gmail.com | P18: Callé agua helada 2535 | Q18: Curicó | R18: 985542454 | S18: Soltero (a) | T18: FONASA | W18: 0 | X18: 18738 | Y18: 18414 | Z18: 13968 | AO18: 0
A19: 18 | B19: 19610872 | C19: 6 | D19: CELEDON MARDONEZ NATALIA NOEMI | F19: 20 | G19: CT | H19: TDA-SPORT HOMBRES | I19: 2866 | J19: Asesor De Clientes | K19: Asesor De Compras | L19: 45019 | M19: =+(TODAY()-L19)/365 -> 1.690411 | N19: 35647 | O19: natalia.celeron.mardonez@gmail.com | P19: Villa Cataluña Barcelona #771 | Q19: Curico | R19: 976033019
A20: 19 | B20: 19998291 | C20: 5 | D20: CONTRERAS ALVAREZ ALEXIA FABIOLA | F20: 30 | G20: CT | H20: TDA-RINCON JUVENIL DAMAS GENERICO | I20: 2866 | J20: Asesor De Clientes | K20: Asesor De Compras | L20: 43374 | M20: =+(TODAY()-L20)/365 -> 6.1972603 | N20: 36102 | W20: 6662 | X20: 6662 | Y20: 11253 | Z20: 8536 | AN20: 2828 | AO20: 514 | AS20: 43544
A21: 20 | B21: 10228847 | C21: 5 | D21: CONTRERAS CASTRO JAQUELINE DEL CARMEN | F21: 20 | G21: CT | H21: TDA-CAJAS | I21: 741 | J21: Cajera(O) - Empaque | K21: Cajera(O) - Empaque | L21: 44826 | M21: =+(TODAY()-L21)/365 -> 2.2191781 | N21: 23695
A22: 21 | B22: 14499879 | C22: 0 | D22: CONTRERAS PEREDO PURISIMA DE LAS MERC | F22: 45 | G22: CT | H22: TDA-NIÑOS (2-6) | I22: 2866 | J22: Asesor De Clientes | K22: Asesor De Compras | L22: 42968 | M22: =+(TODAY()-L22)/365 -> 7.309589 | N22: 27827 | O22: puricontrerasp@gmail.com | P22: Calle Roma 1944 villa Galilea | Q22: Curicó | R22: 996969501 | S22: Casado (a) | T22: FONASA | U22: 60000 | W22: 0 | X22: 18738 | Y22: 11253 | Z22: 8536 | AC22: 30000 | AO22: 154 | AP22: 25000 | AQ22: 338 | AR22: 20000 | AS22: 134804 | AU22: 20000
A23: 22 | B23: 17980549 | C23: 9 | D23: CORNEJO SAAVEDRA KAROL NIDIA | F23: 30 | G23: CT | H23: TDA-RINCON JUVENIL DAMAS GENERICO | I23: 2866 | J23: Asesor De Clientes | K23: Asesor De Compras | L23: 43255 | M23: =+(TODAY()-L23)/365 -> 6.5232877 | N23: 33572 | W23: 12492 | X23: 12492 | Y23: 20460 | Z23: 15520 | AC23: 20000 | AN23: 300 | AO23: 698 | AP23: 16667 | AQ23: 2025 | AR23: 13333 | AS23: 82389 | AU23: 13333
A24: 23 | B24: 15138844 | C24: 2 | D24: DIAZ DIAZ MARIA JOSE | F24: 20 | G24: CT | H24: TDA-CAJAS | I24: 741 | J24: Cajera(O) - Empaque | K24: Cajera(O) - Empaque | L24: 44398 | M24: =+(TODAY()-L24)/365 -> 3.3917808 | N24: 30275 | W24: 8328 | X24: 8328 | Y24: 8184 | Z24: 6208 | AM24: 15875 | AN24: 300 | AO24: 0 | AQ24: 34875 | AT24: 17400
A25: 24 | B25: 21478843 | C25: 8 | D25: DIAZ SEPULVEDA LEONOR MACKARENA | F25: 20 | G25: CT | H25: TDA-SPORT HOMBRES | J25: Asesor De Clientes | L25: 44824 | M25: =+(TODAY()-L25)/365 -> 2.2246575 | N25: 37990
A26: 25 | B26: 13351507 | C26: 0 | D26: DUARTE MIRANDA PRISILA DEL CARMEN | F26: 25 | G26: CT | H26: TDA-AUDIO/VIDEO | I26: 679 | J26: Vendedor(A) | K26: Vendedor(A) | L26: 38384 | M26: =+(TODAY()-L26)/365 -> 19.868493 | N26: 28608 | V26: 9075 | Y26: 18414 | Z26: 13968 | AB26: 11250 | AN26: 224580 | AO26: 82160 | AQ26: 600 | AW26: 8050
A27: 26 | B27: 14287355 | C27: 9 | D27: DURAN VALENZUELA LUIS OSVALDO | F27: 45 | G27: ST | H27: TDA-PREV.PERD. Y PROT.ACTIVOS | I27: 653 | J27: Guardia | K27: Guardia | L27: 38005 | M27: =+(TODAY()-L27)/365 -> 20.906849 | N27: 27347 | W27: 0 | X27: 13117 | Y27: 15345 | Z27: 11640 | AO27: 0
A28: 27 | B28: 17981225 | C28: 8 | D28: ECHEVERRIA NUÑEZ JUAN ROSENDO | F28: 45 | G28: CT | H28: TDA-PREV.PERD. Y PROT.ACTIVOS | I28: 653 | J28: Guardia | K28: Guardia | L28: 42534 | M28: =+(TODAY()-L28)/365 -> 8.4986301 | N28: 33829 | O28: Juan.echeverrianunez.12@gmail.com | P28: Camino pulmodon s/n itahue | Q28: Molina | R28: 999952164 | S28: Soltero (a) | T28: FONASA | W28: 18738 | X28: 18738 | Y28: 21483 | Z28: 16296 | AO28: 0
A29: 28 | B29: 10409683 | C29: 2 | D29: ELUCHANS SANHUEZA HERTA ELENA | F29: 30 | G29: CT | H29: TDA-NIÑOS (2-6) | I29: 2866 | J29: Asesor De Clientes | K29: Asesor De Compras | L29: 44515 | M29: =+(TODAY()-L29)/365 -> 3.0712329 | N29: 24124 | V29: 9571 | W29: 12492 | X29: 12492 | Y29: 21483 | Z29: 16296 | AC29: 20000 | AO29: 0 | AP29: 16667 | AR29: 13333 | AS29: 90377 | AU29: 13333
A30: 29 | B30: 11371360 | C30: 7 | D30: ESPINOZA CERECEDA LUIS FELIX | F30: 45 | G30: ST | H30: TDA-PREV.PERD. Y PROT.ACTIVOS | I30: 653 | J30: Guardia | K30: Guardia | L30: 38671 | M30: =+(TODAY()-L30)/365 -> 19.082192 | N30: 25544 | O30: felix69@live.cl | P30: Bombero Garrido pasaje luciano 1110 | Q30: Curicó | R30: 964250934 | S30: Soltero (a) | T30: ISAPRE | W30: 18738 | X30: 18738 | Y30: 21483 | Z30: 16296 | AO30: 0
A31: 30 | B31: 10466538 | C31: 1 | D31: FAUNDEZ CAMPOS GUILLERMO ESTEBAN | F31: 45 | G31: ST | H31: TDA-PREV.PERD. Y PROT.ACTIVOS | I31: 653 | J31: Guardia | K31: Guardia | L31: 39146 | M31: =+(TODAY()-L31)/365 -> 17.780822 | N31: 24011 | O31: guillermofaundez65@gmail.com | P31: Rauquen don Sebastian calle Le Mans#1256 Curico | Q31: Curicó | R31: 958319011 | S31: Soltero (a) | T31: FONASA | W31: 18738 | X31: 18738 | Y31: 21483 | Z31: 16296 | AH31: 30000 | AO31: 0
A32: 31 | B32: 12416653 | C32: 5 | D32: FUENZALIDA FUENTE RUHAMA PAULINA | F32: 18 | G32: CT | H32: TDA-MUEBLES | I32: 679 | J32: Vendedor(A) | K32: Vendedor(A) | L32: 40182 | M32: =+(TODAY()-L32)/365 -> 14.942466 | N32: 26837 | O32: rpaulinafuenzalida@gmail.com | P32: Mejillones 2 pasaje Isla lifen 0217 | Q32: Curicó | R32: 954465532 | S32: Divorc(a) Separ(a) | T32: FONASA | Y32: 8184 | Z32: 6208 | AB32: 5000 | AN32: 181238 | AO32: 0 | AQ32: 900 | AW32: 12250
A33: 32 | B33: 17374147 | C33: 2 | D33: GATICA CORNEJO JORDAN ALAN | F33: 45 | G33: CT | H33: TDA-DISPLAY | I33: 48 | J33: Asistente De Display | K33: Asistente De Display | L33: 44109 | M33: =+(TODAY()-L33)/365 -> 4.1835616 | N33: 32948 | W33: 0 | X33: 18738 | Y33: 20460 | Z33: 15520 | AO33: 0 | AP33: 10417
A34: 33 | B34: 13352679 | C34: K | D34: GAVILAN ROJAS ISABEL DEL CARMEN | F34: 30 | G34: CT | H34: TDA-CAJAS | I34: 741 | J34: Cajera(O) - Empaque | K34: Cajera(O) - Empaque | L34: 41309 | M34: =+(TODAY()-L34)/365 -> 11.854795 | N34: 28813 | O34: Isabelgavilanrojas0206@gmail.com | P34: Pobl. Sol de sept Lauca 393 | Q34: Curicó | R34: 994959989 | S34: Divorc(a) Separ(a) | T34: FONASA | W34: 12492 | X34: 12492 | Y34: 16368 | Z34: 12416 | AB34: 17019 | AF34: 187500 | AM34: 134375 | AN34: 6300 | AO34: 72928 | AQ34: 52125 | AT34: 18570
A35: 34 | B35: 17795856 | C35: 5 | D35: GONZALEZ SILVA ABRAHAM ELIAS | F35: 45 | G35: CT | H35: TDA-PREV.PERD. Y PROT.ACTIVOS | I35: 653 | J35: Guardia | K35: Guardia | L35: 40679 | M35: =+(TODAY()-L35)/365 -> 13.580822 | N35: 33305 | O35: aegonzalezsilva@gmail.com | P35: Villa Nueva Galilea #2118 | Q35: Curicó | R35: 954453036 | S35: Casado (a) | T35: FONASA | U35: 60000 | V35: 6050 | W35: 18738 | X35: 18738 | Y35: 10230 | Z35: 7760 | AO35: 0
A36: 35 | B36: 17214601 | C36: 5 | D36: GONZALEZ ULLOA VALESCA ALEJANDRA | F36: 20 | G36: CT | H36: TDA-PROBADORES | I36: 2866 | J36: Asesor De Clientes | K36: Asistente De Probadores | L36: 43423 | M36: =+(TODAY()-L36)/365 -> 6.0630137 | N36: 32533 | O36: valescagonzalez25@gmail.com | P36: Bombero Garrido pj san marcos 1862 | Q36: Curicó | R36: 935613179 | S36: Soltero (a) | T36: FONASA | W36: 8328 | X36: 0 | Y36: 7161 | Z36: 5432 | AC36: 13333 | AN36: 1600 | AO36: 0 | AP36: 11111 | AQ36: 3125 | AR36: 8889 | AS36: 40875 | AU36: 8889
A37: 36 | B37: 18577117 | C37: 2 | D37: HERRERA NAVARRO CONSTANZA NICOLE | F37: 45 | G37: CT | H37: TDA-RINCON JUVENIL HOMBRES GENERICO | I37: 2866 | J37: Asesor De Clientes | K37: Asesor De Compras | L37: 43318 | M37: =+(TODAY()-L37)/365 -> 6.3506849 | N37: 34201 | O37: constanza.h19@gmail.com | P37: villa padre hurtado pasaje 7 cardenal antonio samore 1062 | Q37: Curicó | R37: 950259879 | S37: Soltero (a) | T37: FONASA | V37: 3025 | W37: 18738 | X37: 18738 | Y37: 17391 | Z37: 13192 | AC37: 30000 | AL37: 24655 | AO37: 2002 | AP37: 25000 | AQ37: 38 | AR37: 20000 | AS37: 128460 | AU37: 20000
A38: 37 | B38: 15850696 | C38: 3 | D38: HERRERA OLIVOS ANGELO ENRIQUE | F38: 40 | G38: CT | H38: TDA-CALZADO INFANTIL GENERICO | I38: 679 | J38: Vendedor(A) | K38: Vendedor(A) | L38: 38507 | M38: =+(TODAY()-L38)/365 -> 19.531507 | N38: 30966 | Y38: 20460 | Z38: 15520 | AB38: 12500 | AN38: 233427 | AO38: 96755 | AQ38: 4388 | AW38: 84700
A39: 38 | B39: 9503353 | C39: 9 | D39: IBARRA CONCHA TATIANA ISABEL | F39: 45 | G39: ST | H39: TDA- BODEGA CENTRALIZADA | I39: 2865 | J39: Asistente De Bodegas | K39: Asistente De Bodega | L39: 38504 | M39: =+(TODAY()-L39)/365 -> 19.539726 | N39: 22792 | W39: 18738 | X39: 18738 | Y39: 11253 | Z39: 8536 | AA39: 40000 | AC39: 40000 | AI39: 40000 | AO39: 0 | AP39: 25000
A40: 39 | B40: 21284551 | C40: 5 | D40: LEIVA DIAZ LUIS FELIPE | F40: 20 | G40: CT | H40: TDA- BODEGA CENTRALIZADA | I40: 2865 | J40: Asistente De Bodegas | K40: Asistente De Trastienda Calzado | L40: 44473 | M40: =+(TODAY()-L40)/365 -> 3.1863014 | N40: 37733 | W40: 0 | X40: 0 | Y40: 7161 | Z40: 5432 | AA40: 17778 | AC40: 17778 | AI40: 17778 | AO40: 0 | AP40: 11111
...

Sheet Tabla
A2: Cuenta de cargo nuevo | B2: Jor | J2: Cuenta de cargo nuevo | K2: Jor
A3: Etiquetas de fila | B3: 18 | C3: 20 | D3: 25 | E3: 30 | F3: 40 | G3: 45 | H3: Total | J3: Etiquetas de fila | K3: 20 | L3: 30 | M3: 40 | N3: 45 | O3: Total
A4: Asesor De Clientes | C4: 4 | E4: 8 | F4: 2 | G4: 8 | H4: 22 | J4: TDA-CONFECCION DAMAS GENERICO | L4: 3 | O4: 3
A5: Asistente De Bodegas | C5: 1 | G5: 1 | H5: 2 | J5: TDA-CORSETERIA Y LENCERIA GENERICO | N5: 1 | O5: 1
A6: Asistente De Display | E6: 1 | G6: 2 | H6: 3 | J6: TDA-NIÑAS (2-6) | N6: 1 | O6: 1
A7: Cajera(O) - Empaque | C7: 5 | E7: 3 | G7: 1 | H7: 9 | J7: TDA-NIÑOS (2-6) | L7: 1 | N7: 1 | O7: 2
A8: Coordinadora de Ventas | G8: 1 | H8: 1 | J8: TDA-NIÑOS (8-16) | M8: 1 | O8: 1
A9: Encargado De Seguridad | G9: 1 | H9: 1 | J9: TDA-PERFUMERIA SELECTIVA GENERICA | K9: 1 | L9: 1 | O9: 2
A10: Guardia | C10: 2 | G10: 13 | H10: 15 | J10: TDA-PICK UP IN STORE | N10: 2 | O10: 2
A11: Vendedor(A) | B11: 1 | D11: 3 | E11: 4 | F11: 4 | G11: 4 | H11: 16 | J11: TDA-PROBADORES | K11: 1 | O11: 1
A12: Consultor Perfumeria | C12: 1 | G12: 1 | H12: 2 | J12: TDA-RINCON JUVENIL DAMAS GENERICO | L12: 2 | M12: 1 | O12: 3
A13: Trainee De Seguridad | C13: 2 | G13: 1 | H13: 3 | J13: TDA-RINCON JUVENIL HOMBRES GENERICO | N13: 1 | O13: 1
A14: Total | B14: 1 | C14: 15 | D14: 3 | E14: 16 | F14: 6 | G14: 33 | H14: 74 | J14: TDA-SPORT DAMAS GENERICO | N14: 1 | O14: 1
J15: TDA-SPORT HOMBRES | K15: 2 | L15: 1 | O15: 3
J16: TDA-TEXTIL | N16: 1 | O16: 1
J17: Total | K17: 4 | L17: 8 | M17: 2 | N17: 8 | O17: 22

Sheet Depto Cargo
A2: Departamento | B2: (Todas)
A3: Cargo | B3: (Todas)
A5: Cuenta de Jor | C5: Jor
A6: Sindicato | B6: Nombre Completo Empleado | C6: 10 | D6: 18 | E6: 20 | F6: 25 | G6: 30 | H6: 40 | I6: 45 | J6: Total
A7: Sind. N° 1 | C7: 1 | D7: 2 | E7: 15 | F7: 1 | G7: 13 | H7: 9 | I7: 26 | J7: 67
A8: STFC | D8: 1 | E8: 12 | F8: 3 | G8: 16 | H8: 5 | I8: 35 | J8: 72
A9: Total | C9: 1 | D9: 3 | E9: 27 | F9: 4 | G9: 29 | H9: 14 | I9: 61 | J9: 139

Sheet Reuniones 2023
B1: REUNION SINDICAL 23-03-2023 (INF. TESORERIA) | G1: REUNION SINDICAL 10 DE MAYO 2023 (NEG. COL.) | L1: REUNION SINDICAL 9 DE junio 2023 (NEG. COL.) | Q1: SALIDA DE REDES SOCIALES 11-8 | V1: 29-08-2023 APROBACION DE NEGOCIACION 2023 | AA1: REUNION SINDICAL (5 de julio 2024)
B2: Rut | C2: DV | D2: Nombre Completo Empleado | E2: ASISTE | G2: Rut | H2: DV | I2: Nombre Completo Empleado | J2: ASISTE | L2: Rut | M2: DV | N2: Nombre Completo Empleado | O2: ASISTE | Q2: Rut | R2: DV | S2: Nombre Completo Empleado | T2: SUMA | V2: Rut | W2: DV | X2: Nombre Completo Empleado | Y2: Voto | AA2: Rut | AB2: DV | AC2: Nombre Completo Empleado | AD2: ASISTE
A3: =+COUNTIF(E3:AD3,"SI") -> 4 | B3: 13785813 | C3: 4 | D3: AGUILAR OYARZO LORETO SAN JUAN | E3: SI | G3: 13785813 | H3: 4 | I3: AGUILAR OYARZO LORETO SAN JUAN | J3: NO | L3: 13785813 | M3: 4 | N3: AGUILAR OYARZO LORETO SAN JUAN | O3: SI | Q3: 13785813 | R3: 4 | S3: AGUILAR OYARZO LORETO SAN JUAN | T3: SI | V3: 13785813 | W3: 4 | X3: AGUILAR OYARZO LORETO SAN JUAN | Y3: SI | AA3: =+STFC!B2 -> 13785813 | AB3: =+STFC!C2 -> 4 | AC3: =+STFC!D2 -> AGUILAR OYARZO LORETO SAN JUAN
A4: =+COUNTIF(E4:AD4,"SI") -> 1 | B4: 17155397 | C4: 0 | D4: AGUILERA AGUILERA JEREMY ALEXSANDER | E4: NO | G4: 17155397 | H4: 0 | I4: AGUILERA AGUILERA JEREMY ALEXSANDER | J4: NO | L4: 17155397 | M4: 0 | N4: AGUILERA AGUILERA JEREMY ALEXSANDER | O4: SI | Q4: 17155397 | R4: 0 | S4: AGUILERA AGUILERA JEREMY ALEXSANDER | T4: NO | V4: 17155397 | W4: 0 | X4: AGUILERA AGUILERA JEREMY ALEXSANDER | Y4: NO | AA4: =+STFC!B3 -> 17155397 | AB4: =+STFC!C3 -> 0 | AC4: =+STFC!D3 -> AGUILERA AGUILERA JEREMY ALEXSANDER
A5: =+COUNTIF(E5:AD5,"SI") -> 1 | B5: 14399370 | C5: 1 | D5: APABLAZA RUZ MARIA XIMENA | E5: NO | G5: 14399370 | H5: 1 | I5: APABLAZA RUZ MARIA XIMENA | J5: NO | L5: 14399370 | M5: 1 | N5: APABLAZA RUZ MARIA XIMENA | O5: NO | Q5: 14399370 | R5: 1 | S5: APABLAZA RUZ MARIA XIMENA | T5: SI | V5: 14399370 | W5: 1 | X5: APABLAZA RUZ MARIA XIMENA | Y5: NO | AA5: =+STFC!B4 -> 14399370 | AB5: =+STFC!C4 -> 1 | AC5: =+STFC!D4 -> APABLAZA RUZ MARIA XIMENA
A6: =+COUNTIF(E6:AD6,"SI") -> 3 | B6: 17441446 | C6: 7 | D6: ARANIZ MARTINEZ DENISSE VANESSA | E6: SI | G6: 17441446 | H6: 7 | I6: ARANIZ MARTINEZ DENISSE VANESSA | J6: NO | L6: 17441446 | M6: 7 | N6: ARANIZ MARTINEZ DENISSE VANESSA | O6: NO | Q6: 17441446 | R6: 7 | S6: ARANIZ MARTINEZ DENISSE VANESSA | T6: SI | V6: 17441446 | W6: 7 | X6: ARANIZ MARTINEZ DENISSE VANESSA | Y6: SI | AA6: =+STFC!B5 -> 17441446 | AB6: =+STFC!C5 -> 7 | AC6: =+STFC!D5 -> ARANIZ MARTINEZ DENISSE VANESSA
A7: =+COUNTIF(E7:AD7,"SI") -> 1 | B7: 20509180 | C7: 7 | D7: AVENDAÑO TORREJON NICOLE ALEXIS | E7: NO | G7: 20509180 | H7: 7 | I7: AVENDAÑO TORREJON NICOLE ALEXIS | J7: NO | L7: 20509180 | M7: 7 | N7: AVENDAÑO TORREJON NICOLE ALEXIS | O7: NO | Q7: 20509180 | R7: 7 | S7: AVENDAÑO TORREJON NICOLE ALEXIS | T7: SI | V7: 20509180 | W7: 7 | X7: AVENDAÑO TORREJON NICOLE ALEXIS | Y7: NO | AA7: =+STFC!B6 -> 16858860 | AB7: =+STFC!C6 -> 7 | AC7: =+STFC!D6 -> ARAVENA VASQUEZ RITA NORMA
A8: =+COUNTIF(E8:AD8,"SI") -> 0 | B8: 20122174 | C8: 9 | D8: BECERRA BECERRA KARIM CAMILA | G8: 20122174 | H8: 9 | I8: BECERRA BECERRA KARIM CAMILA | L8: 20122174 | M8: 9 | N8: BECERRA BECERRA KARIM CAMILA | Q8: 20122174 | R8: 9 | S8: BECERRA BECERRA KARIM CAMILA | T8: NO | V8: 16858860 | W8: 7 | X8: ARAVENA VASQUEZ RITA NORMA | Y8: NO | AA8: =+STFC!B7 -> 20178047 | AB8: =+STFC!C7 -> 0 | AC8: =+STFC!D7 -> BARRIOS REYES JOAQUIN FERNANDO
A9: =+COUNTIF(E9:AD9,"SI") -> 3 | B9: 17155794 | C9: 1 | D9: BRAVO MORALES JOSE LUIS | E9: NO | G9: 17155794 | H9: 1 | I9: BRAVO MORALES JOSE LUIS | J9: SI | L9: 17155794 | M9: 1 | N9: BRAVO MORALES JOSE LUIS | O9: NO | Q9: 17155794 | R9: 1 | S9: BRAVO MORALES JOSE LUIS | T9: SI | V9: 20122174 | W9: 9 | X9: BECERRA BECERRA KARIM CAMILA | Y9: SI | AA9: =+STFC!B8 -> 20122174 | AB9: =+STFC!C8 -> 9 | AC9: =+STFC!D8 -> BECERRA BECERRA KARIM CAMILA
A10: =+COUNTIF(E10:AD10,"SI") -> 3 | B10: 15850392 | C10: 1 | D10: BUENO CUETO RICARDO ANTONIO | E10: NO | G10: 15850392 | H10: 1 | I10: BUENO CUETO RICARDO ANTONIO | J10: SI | L10: 15850392 | M10: 1 | N10: BUENO CUETO RICARDO ANTONIO | O10: SI | Q10: 15850392 | R10: 1 | S10: BUENO CUETO RICARDO ANTONIO | T10: SI | V10: 18028807 | W10: 4 | X10: BERNAL BAHAMONDES LUIS FELIPE | Y10: NO | AA10: =+STFC!B9 -> 18028807 | AB10: =+STFC!C9 -> 4 | AC10: =+STFC!D9 -> BERNAL BAHAMONDES LUIS FELIPE
A11: =+COUNTIF(E11:AD11,"SI") -> 1 | B11: 21609803 | C11: K | D11: BUSTOS VARELA MARIA PAZ | E11: NO | G11: 21609803 | H11: K | I11: BUSTOS VARELA MARIA PAZ | J11: NO | L11: 21609803 | M11: K | N11: BUSTOS VARELA MARIA PAZ | O11: NO | Q11: 21609803 | R11: K | S11: BUSTOS VARELA MARIA PAZ | T11: SI | V11: 20663038 | W11: 8 | X11: BRAVO ALISTE CONSTANZA SOLEDAD | Y11: NO | AA11: =+STFC!B10 -> 20663038 | AB11: =+STFC!C10 -> 8 | AC11: =+STFC!D10 -> BRAVO ALISTE CONSTANZA SOLEDAD
A12: =+COUNTIF(E12:AD12,"SI") -> 2 | B12: 17592613 | C12: 5 | D12: CALIBAR JARA BARBARA CONSUELO | G12: 17592613 | H12: 5 | I12: CALIBAR JARA BARBARA CONSUELO | L12: 17592613 | M12: 5 | N12: CALIBAR JARA BARBARA CONSUELO | Q12: 17592613 | R12: 5 | S12: CALIBAR JARA BARBARA CONSUELO | T12: SI | V12: 17155794 | W12: 1 | X12: BRAVO MORALES JOSE LUIS | Y12: SI | AA12: =+STFC!B11 -> 17155794 | AB12: =+STFC!C11 -> 1 | AC12: =+STFC!D11 -> BRAVO MORALES JOSE LUIS
A13: =+COUNTIF(E13:AD13,"SI") -> 2 | B13: 14051199 | C13: 4 | D13: CANALES JUICA CAROLINA ANDREA | E13: NO | G13: 14051199 | H13: 4 | I13: CANALES JUICA CAROLINA ANDREA | J13: NO | L13: 14051199 | M13: 4 | N13: CANALES JUICA CAROLINA ANDREA | O13: NO | Q13: 14051199 | R13: 4 | S13: CANALES JUICA CAROLINA ANDREA | T13: SI | V13: 15850392 | W13: 1 | X13: BUENO CUETO RICARDO ANTONIO | Y13: SI | AA13: =+STFC!B12 -> 15850392 | AB13: =+STFC!C12 -> 1 | AC13: =+STFC!D12 -> BUENO CUETO RICARDO ANTONIO
A14: =+COUNTIF(E14:AD14,"SI") -> 4 | B14: 20509166 | C14: 1 | D14: CARIAGA GAVILAN GENESIS ISAMAR | E14: SI | G14: 20509166 | H14: 1 | I14: CARIAGA GAVILAN GENESIS ISAMAR | J14: SI | L14: 20509166 | M14: 1 | N14: CARIAGA GAVILAN GENESIS ISAMAR | O14: SI | Q14: 20509166 | R14: 1 | S14: CARIAGA GAVILAN GENESIS ISAMAR | T14: SI | V14: 21609803 | W14: K | X14: BUSTOS VARELA MARIA PAZ | Y14: NO | AA14: =+STFC!B13 -> 21609803 | AB14: =+STFC!C13 -> K | AC14: =+STFC!D13 -> BUSTOS VARELA MARIA PAZ
A15: =+COUNTIF(E15:AD15,"SI") -> 4 | B15: 10658936 | C15: 4 | D15: CARRASCO RAMIREZ MARISOL DEL CARMEN | E15: SI | G15: 10658936 | H15: 4 | I15: CARRASCO RAMIREZ MARISOL DEL CARMEN | J15: SI | L15: 10658936 | M15: 4 | N15: CARRASCO RAMIREZ MARISOL DEL CARMEN | O15: NO | Q15: 10658936 | R15: 4 | S15: CARRASCO RAMIREZ MARISOL DEL CARMEN | T15: SI | V15: 17592613 | W15: 5 | X15: CALIBAR JARA BARBARA CONSUELO | Y15: SI | AA15: =+STFC!B14 -> 19768878 | AB15: =+STFC!C14 -> 5 | AC15: =+STFC!D14 -> CABRERA LLEVENES ESCARLET BELEN
